<?xml version="1.0"?>
<robot name="diff_drive_robot">

  <!-- base -->
  <link name="base_link">
    <inertial>
      <origin xyz="0 0 0" rpy="0 0 0"/>
      <mass value="5.0"/>
      <inertia ixx="0.1" ixy="0.0" ixz="0.0"
               iyy="0.1" iyz="0.0" izz="0.1"/>
    </inertial>

    <visual>
      <origin xyz="0 0 0.25" rpy="0 0 0"/>
      <geometry>
        <cylinder radius="0.3" length="0.1"/>
      </geometry>
      <material name="gray">
        <color rgba="0.8 0.8 0.8 1.0"/>
      </material>
    </visual>

    <collision>
      <origin xyz="0 0 0.25" rpy="0 0 0"/>
      <geometry>
        <cylinder radius="0.3" length="0.1"/>
      </geometry>
    </collision>
  </link>

  <link name="base_footprint"/>

<joint name="base_footprint_joint" type="fixed">
  <parent link="base_footprint"/>
  <child link="base_link"/>
  <origin xyz="0 0 0"/>
</joint>


  <!-- LEFT WHEEL -->
  <link name="left_wheel_link">
    <inertial>
      <origin xyz="0 0 0"/>
      <mass value="1.0"/>
      <inertia ixx="0.01" ixy="0" ixz="0"
               iyy="0.01" iyz="0" izz="0.01"/>
    </inertial>

    <visual>
      <origin xyz="0 0 0" rpy="1.5708 0 0"/>
      <geometry>
        <cylinder radius="0.1" length="0.1"/>
      </geometry>
      <material name="black">
        <color rgba="0.1 0.0 0.1 1.0"/>
      </material>
    </visual>

    <collision>
      <origin xyz="0 0 0" rpy="1.5708 0 0"/>
      <geometry>
        <cylinder radius="0.1" length="0.1"/>
      </geometry>
    </collision>
  </link>


<joint name="left_wheel_joint" type="continuous">
  <parent link="base_link"/>
  <child link="left_wheel_link"/>
  <origin xyz="0 0.25 0.1"/>
  <axis xyz="0 1 0"/>
  <limit effort="10.0" velocity="10.0"/>
</joint>


  <!-- RIGHT WHEEL -->
  <link name="right_wheel_link">
    <inertial>
      <origin xyz="0 0 0"/>
      <mass value="1.0"/>
      <inertia ixx="0.01" ixy="0" ixz="0"
               iyy="0.01" iyz="0" izz="0.01"/>
    </inertial>

    <visual>
      <origin xyz="0 0 0" rpy="1.5708 0 0"/>
      <geometry>
        <cylinder radius="0.1" length="0.1"/>
      </geometry>
      <material name="black">
        <color rgba="0.1 0.1 0.1 1.0"/>
      </material>
    </visual>

    <collision>
      <origin xyz="0 0 0" rpy="1.5708 0 0"/>
      <geometry>
        <cylinder radius="0.1" length="0.1"/>
      </geometry>
    </collision>
  </link>


<joint name="right_wheel_joint" type="continuous">
  <parent link="base_link"/>
  <child link="right_wheel_link"/>
  <origin xyz="0 -0.25 0.1"/>
  <axis xyz="0 1 0"/>
  <limit effort="10.0" velocity="10.0"/>
</joint>



  <!-- *************** IMU **************** -->

  <link name="zed_imu_link">
    <inertial>
      <origin xyz="0 0 0"/>
      <mass value="0.05"/>
      <inertia ixx="1e-5" ixy="0" ixz="0"
               iyy="1e-5" iyz="0" izz="1e-5"/>
    </inertial>

    <visual>
      <origin xyz="0 0 0"/>
      <geometry>
        <box size="0.02 0.02 0.02"/>
      </geometry>
      <material name="imu_frame">
        <color rgba="1.0 1.0 0.0 1.0"/>
      </material>
    </visual>

    <collision>
      <origin xyz="0 0 0"/>
      <geometry>
        <box size="0.02 0.02 0.02"/>
      </geometry>
    </collision>
  </link>

  <joint name="zed_imu_joint" type="fixed">
    <parent link="base_link"/>
    <child link="zed_imu_link"/>
    <origin xyz="0.05 0 0.31"/>
  </joint>



  <!-- *************** LIDAR **************** -->

  <link name="rplidar_c1">
    <inertial>
      <origin xyz="0 0 0"/>
      <mass value="0.4"/>
      <inertia ixx="1e-4" ixy="0" ixz="0"
               iyy="1e-4" iyz="0" izz="2e-4"/>
    </inertial>

    <visual>
      <origin xyz="0 0 0"/>
      <geometry>
        <cylinder radius="0.1" length="0.1"/>
      </geometry>
      <material name="rplidar_c1">
        <color rgba="1.0 0.5 0.0 1.0"/>
      </material>
    </visual>

    <collision>
      <origin xyz="0 0 0"/>
      <geometry>
        <cylinder radius="0.1" length="0.1"/>
      </geometry>
    </collision>
  </link>

  <joint name="rplidar_joint" type="fixed">
    <parent link="base_link"/>
    <child link="rplidar_c1"/>
    <origin xyz="0 0 0.35"/>
  </joint>




  <!-- =========== GAZEBO PLUGINS =============== -->

  <!-- IMU Plugin -->
  <gazebo>
    <plugin filename="libignition-gazebo-imu-system"
            name="ignition::gazebo::systems::Imu"/>
  </gazebo>

  <gazebo reference="zed_imu_link">
    <sensor name="imu_sensor" type="imu">
      <always_on>true</always_on>
      <update_rate>100</update_rate>
      <visualize>true</visualize>
      <topic>/zed/zed_node/imu/data_raw</topic>
    </sensor>
  </gazebo>

  <!-- LIDAR Plugin -->
  <gazebo reference="rplidar_c1">
    <sensor type="gpu_lidar" name="rplidar_c1_sensor">
      <always_on>true</always_on>
      <visualize>true</visualize>
      <update_rate>20</update_rate>
      <topic>/gz_lidar/points</topic>
      <lidar>
        <scan>
          <horizontal>
            <samples>720</samples>
            <resolution>1</resolution>
            <min_angle>-3.14</min_angle>
            <max_angle>3.14</max_angle>
          </horizontal>
          <vertical>
            <samples>32</samples>
            <resolution>1</resolution>
            <min_angle>-0.5</min_angle>
            <max_angle>0.5</max_angle>
          </vertical>
        </scan>

        <range>
          <min>0.8</min>
          <max>60.0</max>
          <resolution>0.01</resolution>
        </range>

        <noise>
          <type>gaussian</type>
          <mean>0.0</mean>
          <stddev>0.01</stddev>
        </noise>

      </lidar>
    </sensor>
  </gazebo>


</robot>